[2025-10-05T23:02:03.660+0000] {taskinstance.py:1159} INFO - Dependencies all met for dep_context=non-requeueable deps ti=<TaskInstance: forest_cover_training_pipeline.fetch_data scheduled__2025-10-05T22:50:00+00:00 [queued]>
[2025-10-05T23:02:03.743+0000] {taskinstance.py:1159} INFO - Dependencies all met for dep_context=requeueable deps ti=<TaskInstance: forest_cover_training_pipeline.fetch_data scheduled__2025-10-05T22:50:00+00:00 [queued]>
[2025-10-05T23:02:03.743+0000] {taskinstance.py:1361} INFO - Starting attempt 2 of 2
[2025-10-05T23:02:03.749+0000] {taskinstance.py:1382} INFO - Executing <Task(PythonOperator): fetch_data> on 2025-10-05 22:50:00+00:00
[2025-10-05T23:02:03.754+0000] {standard_task_runner.py:57} INFO - Started process 1694 to run task
[2025-10-05T23:02:03.757+0000] {standard_task_runner.py:84} INFO - Running: ['***', 'tasks', 'run', 'forest_cover_training_pipeline', 'fetch_data', 'scheduled__2025-10-05T22:50:00+00:00', '--job-id', '26', '--raw', '--subdir', 'DAGS_FOLDER/training_pipeline.py', '--cfg-path', '/tmp/tmpk5j4ut9_']
[2025-10-05T23:02:03.759+0000] {standard_task_runner.py:85} INFO - Job 26: Subtask fetch_data
[2025-10-05T23:02:03.797+0000] {task_command.py:416} INFO - Running <TaskInstance: forest_cover_training_pipeline.fetch_data scheduled__2025-10-05T22:50:00+00:00 [running]> on host 4c3e0b03c920
[2025-10-05T23:02:03.843+0000] {taskinstance.py:1662} INFO - Exporting env vars: AIRFLOW_CTX_DAG_OWNER='mlops_team' AIRFLOW_CTX_DAG_ID='forest_cover_training_pipeline' AIRFLOW_CTX_TASK_ID='fetch_data' AIRFLOW_CTX_EXECUTION_DATE='2025-10-05T22:50:00+00:00' AIRFLOW_CTX_TRY_NUMBER='2' AIRFLOW_CTX_DAG_RUN_ID='scheduled__2025-10-05T22:50:00+00:00'
[2025-10-05T23:02:03.844+0000] {training_pipeline.py:66} INFO - Solicitando datos desde http://10.43.101.149:80/data con params={'group_number': '6'}
[2025-10-05T23:03:03.907+0000] {training_pipeline.py:81} ERROR - Error de conexi√≥n al API: HTTPConnectionPool(host='10.43.101.149', port=80): Max retries exceeded with url: /data?group_number=6 (Caused by ConnectTimeoutError(<urllib3.connection.HTTPConnection object at 0xffff8ab5fac0>, 'Connection to 10.43.101.149 timed out. (connect timeout=60)'))
[2025-10-05T23:03:03.926+0000] {taskinstance.py:1937} ERROR - Task failed with exception
Traceback (most recent call last):
  File "/home/airflow/.local/lib/python3.10/site-packages/urllib3/connection.py", line 174, in _new_conn
    conn = connection.create_connection(
  File "/home/airflow/.local/lib/python3.10/site-packages/urllib3/util/connection.py", line 95, in create_connection
    raise err
  File "/home/airflow/.local/lib/python3.10/site-packages/urllib3/util/connection.py", line 85, in create_connection
    sock.connect(sa)
TimeoutError: timed out

During handling of the above exception, another exception occurred:

Traceback (most recent call last):
  File "/home/airflow/.local/lib/python3.10/site-packages/urllib3/connectionpool.py", line 715, in urlopen
    httplib_response = self._make_request(
  File "/home/airflow/.local/lib/python3.10/site-packages/urllib3/connectionpool.py", line 416, in _make_request
    conn.request(method, url, **httplib_request_kw)
  File "/home/airflow/.local/lib/python3.10/site-packages/urllib3/connection.py", line 244, in request
    super(HTTPConnection, self).request(method, url, body=body, headers=headers)
  File "/usr/local/lib/python3.10/http/client.py", line 1283, in request
    self._send_request(method, url, body, headers, encode_chunked)
  File "/usr/local/lib/python3.10/http/client.py", line 1329, in _send_request
    self.endheaders(body, encode_chunked=encode_chunked)
  File "/usr/local/lib/python3.10/http/client.py", line 1278, in endheaders
    self._send_output(message_body, encode_chunked=encode_chunked)
  File "/usr/local/lib/python3.10/http/client.py", line 1038, in _send_output
    self.send(msg)
  File "/usr/local/lib/python3.10/http/client.py", line 976, in send
    self.connect()
  File "/home/airflow/.local/lib/python3.10/site-packages/urllib3/connection.py", line 205, in connect
    conn = self._new_conn()
  File "/home/airflow/.local/lib/python3.10/site-packages/urllib3/connection.py", line 179, in _new_conn
    raise ConnectTimeoutError(
urllib3.exceptions.ConnectTimeoutError: (<urllib3.connection.HTTPConnection object at 0xffff8ab5fac0>, 'Connection to 10.43.101.149 timed out. (connect timeout=60)')

During handling of the above exception, another exception occurred:

Traceback (most recent call last):
  File "/home/airflow/.local/lib/python3.10/site-packages/requests/adapters.py", line 486, in send
    resp = conn.urlopen(
  File "/home/airflow/.local/lib/python3.10/site-packages/urllib3/connectionpool.py", line 799, in urlopen
    retries = retries.increment(
  File "/home/airflow/.local/lib/python3.10/site-packages/urllib3/util/retry.py", line 592, in increment
    raise MaxRetryError(_pool, url, error or ResponseError(cause))
urllib3.exceptions.MaxRetryError: HTTPConnectionPool(host='10.43.101.149', port=80): Max retries exceeded with url: /data?group_number=6 (Caused by ConnectTimeoutError(<urllib3.connection.HTTPConnection object at 0xffff8ab5fac0>, 'Connection to 10.43.101.149 timed out. (connect timeout=60)'))

During handling of the above exception, another exception occurred:

Traceback (most recent call last):
  File "/home/airflow/.local/lib/python3.10/site-packages/airflow/operators/python.py", line 192, in execute
    return_value = self.execute_callable()
  File "/home/airflow/.local/lib/python3.10/site-packages/airflow/operators/python.py", line 209, in execute_callable
    return self.python_callable(*self.op_args, **self.op_kwargs)
  File "/opt/airflow/dags/training_pipeline.py", line 67, in fetch_data_from_api
    r = requests.get(url, params=params, timeout=60)
  File "/home/airflow/.local/lib/python3.10/site-packages/requests/api.py", line 73, in get
    return request("get", url, params=params, **kwargs)
  File "/home/airflow/.local/lib/python3.10/site-packages/requests/api.py", line 59, in request
    return session.request(method=method, url=url, **kwargs)
  File "/home/airflow/.local/lib/python3.10/site-packages/requests/sessions.py", line 589, in request
    resp = self.send(prep, **send_kwargs)
  File "/home/airflow/.local/lib/python3.10/site-packages/requests/sessions.py", line 703, in send
    r = adapter.send(request, **kwargs)
  File "/home/airflow/.local/lib/python3.10/site-packages/requests/adapters.py", line 507, in send
    raise ConnectTimeout(e, request=request)
requests.exceptions.ConnectTimeout: HTTPConnectionPool(host='10.43.101.149', port=80): Max retries exceeded with url: /data?group_number=6 (Caused by ConnectTimeoutError(<urllib3.connection.HTTPConnection object at 0xffff8ab5fac0>, 'Connection to 10.43.101.149 timed out. (connect timeout=60)'))
[2025-10-05T23:03:03.970+0000] {taskinstance.py:1400} INFO - Marking task as FAILED. dag_id=forest_cover_training_pipeline, task_id=fetch_data, execution_date=20251005T225000, start_date=20251005T230203, end_date=20251005T230303
[2025-10-05T23:03:03.991+0000] {standard_task_runner.py:104} ERROR - Failed to execute job 26 for task fetch_data (HTTPConnectionPool(host='10.43.101.149', port=80): Max retries exceeded with url: /data?group_number=6 (Caused by ConnectTimeoutError(<urllib3.connection.HTTPConnection object at 0xffff8ab5fac0>, 'Connection to 10.43.101.149 timed out. (connect timeout=60)')); 1694)
[2025-10-05T23:03:04.008+0000] {local_task_job_runner.py:228} INFO - Task exited with return code 1
[2025-10-05T23:03:04.038+0000] {taskinstance.py:2778} INFO - 0 downstream tasks scheduled from follow-on schedule check
