[2025-10-06T02:20:08.107+0000] {taskinstance.py:1159} INFO - Dependencies all met for dep_context=non-requeueable deps ti=<TaskInstance: forest_cover_training_pipeline.train_models scheduled__2025-10-06T02:10:00+00:00 [queued]>
[2025-10-06T02:20:08.237+0000] {taskinstance.py:1159} INFO - Dependencies all met for dep_context=requeueable deps ti=<TaskInstance: forest_cover_training_pipeline.train_models scheduled__2025-10-06T02:10:00+00:00 [queued]>
[2025-10-06T02:20:08.237+0000] {taskinstance.py:1361} INFO - Starting attempt 1 of 2
[2025-10-06T02:20:08.244+0000] {taskinstance.py:1382} INFO - Executing <Task(PythonOperator): train_models> on 2025-10-06 02:10:00+00:00
[2025-10-06T02:20:08.249+0000] {standard_task_runner.py:57} INFO - Started process 670 to run task
[2025-10-06T02:20:08.252+0000] {standard_task_runner.py:84} INFO - Running: ['***', 'tasks', 'run', 'forest_cover_training_pipeline', 'train_models', 'scheduled__2025-10-06T02:10:00+00:00', '--job-id', '14', '--raw', '--subdir', 'DAGS_FOLDER/training_pipeline.py', '--cfg-path', '/tmp/tmp05y__mvm']
[2025-10-06T02:20:08.254+0000] {standard_task_runner.py:85} INFO - Job 14: Subtask train_models
[2025-10-06T02:20:08.283+0000] {task_command.py:416} INFO - Running <TaskInstance: forest_cover_training_pipeline.train_models scheduled__2025-10-06T02:10:00+00:00 [running]> on host 2d6451742e7c
[2025-10-06T02:20:08.320+0000] {taskinstance.py:1662} INFO - Exporting env vars: AIRFLOW_CTX_DAG_OWNER='mlops_team' AIRFLOW_CTX_DAG_ID='forest_cover_training_pipeline' AIRFLOW_CTX_TASK_ID='train_models' AIRFLOW_CTX_EXECUTION_DATE='2025-10-06T02:10:00+00:00' AIRFLOW_CTX_TRY_NUMBER='1' AIRFLOW_CTX_DAG_RUN_ID='scheduled__2025-10-06T02:10:00+00:00'
[2025-10-06T02:20:39.416+0000] {connectionpool.py:824} WARNING - Retrying (JitteredRetry(total=4, connect=5, read=4, redirect=5, status=5)) after connection broken by 'ProtocolError('Connection aborted.', RemoteDisconnected('Remote end closed connection without response'))': /api/2.0/mlflow/experiments/get-by-name?experiment_name=forest_cover_classification
[2025-10-06T02:21:14.158+0000] {connectionpool.py:824} WARNING - Retrying (JitteredRetry(total=3, connect=5, read=3, redirect=5, status=5)) after connection broken by 'ProtocolError('Connection aborted.', RemoteDisconnected('Remote end closed connection without response'))': /api/2.0/mlflow/experiments/get-by-name?experiment_name=forest_cover_classification
[2025-10-06T02:21:52.747+0000] {connectionpool.py:824} WARNING - Retrying (JitteredRetry(total=2, connect=5, read=2, redirect=5, status=5)) after connection broken by 'ProtocolError('Connection aborted.', RemoteDisconnected('Remote end closed connection without response'))': /api/2.0/mlflow/experiments/get-by-name?experiment_name=forest_cover_classification
[2025-10-06T02:22:39.328+0000] {connectionpool.py:824} WARNING - Retrying (JitteredRetry(total=1, connect=5, read=1, redirect=5, status=5)) after connection broken by 'ProtocolError('Connection aborted.', RemoteDisconnected('Remote end closed connection without response'))': /api/2.0/mlflow/experiments/get-by-name?experiment_name=forest_cover_classification
[2025-10-06T02:23:42.038+0000] {connectionpool.py:824} WARNING - Retrying (JitteredRetry(total=0, connect=5, read=0, redirect=5, status=5)) after connection broken by 'ProtocolError('Connection aborted.', RemoteDisconnected('Remote end closed connection without response'))': /api/2.0/mlflow/experiments/get-by-name?experiment_name=forest_cover_classification
[2025-10-06T02:24:12.596+0000] {taskinstance.py:1937} ERROR - Task failed with exception
Traceback (most recent call last):
  File "/home/airflow/.local/lib/python3.10/site-packages/urllib3/connectionpool.py", line 715, in urlopen
    httplib_response = self._make_request(
  File "/home/airflow/.local/lib/python3.10/site-packages/urllib3/connectionpool.py", line 467, in _make_request
    six.raise_from(e, None)
  File "<string>", line 3, in raise_from
  File "/home/airflow/.local/lib/python3.10/site-packages/urllib3/connectionpool.py", line 462, in _make_request
    httplib_response = conn.getresponse()
  File "/usr/local/lib/python3.10/http/client.py", line 1375, in getresponse
    response.begin()
  File "/usr/local/lib/python3.10/http/client.py", line 318, in begin
    version, status, reason = self._read_status()
  File "/usr/local/lib/python3.10/http/client.py", line 287, in _read_status
    raise RemoteDisconnected("Remote end closed connection without"
http.client.RemoteDisconnected: Remote end closed connection without response

During handling of the above exception, another exception occurred:

Traceback (most recent call last):
  File "/home/airflow/.local/lib/python3.10/site-packages/requests/adapters.py", line 486, in send
    resp = conn.urlopen(
  File "/home/airflow/.local/lib/python3.10/site-packages/urllib3/connectionpool.py", line 827, in urlopen
    return self.urlopen(
  File "/home/airflow/.local/lib/python3.10/site-packages/urllib3/connectionpool.py", line 827, in urlopen
    return self.urlopen(
  File "/home/airflow/.local/lib/python3.10/site-packages/urllib3/connectionpool.py", line 827, in urlopen
    return self.urlopen(
  [Previous line repeated 2 more times]
  File "/home/airflow/.local/lib/python3.10/site-packages/urllib3/connectionpool.py", line 799, in urlopen
    retries = retries.increment(
  File "/home/airflow/.local/lib/python3.10/site-packages/urllib3/util/retry.py", line 592, in increment
    raise MaxRetryError(_pool, url, error or ResponseError(cause))
urllib3.exceptions.MaxRetryError: HTTPConnectionPool(host='mlflow', port=5000): Max retries exceeded with url: /api/2.0/mlflow/experiments/get-by-name?experiment_name=forest_cover_classification (Caused by ProtocolError('Connection aborted.', RemoteDisconnected('Remote end closed connection without response')))

During handling of the above exception, another exception occurred:

Traceback (most recent call last):
  File "/home/airflow/.local/lib/python3.10/site-packages/mlflow/utils/rest_utils.py", line 107, in http_request
    return _get_http_response_with_retries(
  File "/home/airflow/.local/lib/python3.10/site-packages/mlflow/utils/request_utils.py", line 197, in _get_http_response_with_retries
    return session.request(method, url, allow_redirects=allow_redirects, **kwargs)
  File "/home/airflow/.local/lib/python3.10/site-packages/requests/sessions.py", line 589, in request
    resp = self.send(prep, **send_kwargs)
  File "/home/airflow/.local/lib/python3.10/site-packages/requests/sessions.py", line 703, in send
    r = adapter.send(request, **kwargs)
  File "/home/airflow/.local/lib/python3.10/site-packages/requests/adapters.py", line 519, in send
    raise ConnectionError(e, request=request)
requests.exceptions.ConnectionError: HTTPConnectionPool(host='mlflow', port=5000): Max retries exceeded with url: /api/2.0/mlflow/experiments/get-by-name?experiment_name=forest_cover_classification (Caused by ProtocolError('Connection aborted.', RemoteDisconnected('Remote end closed connection without response')))

During handling of the above exception, another exception occurred:

Traceback (most recent call last):
  File "/home/airflow/.local/lib/python3.10/site-packages/airflow/operators/python.py", line 192, in execute
    return_value = self.execute_callable()
  File "/home/airflow/.local/lib/python3.10/site-packages/airflow/operators/python.py", line 209, in execute_callable
    return self.python_callable(*self.op_args, **self.op_kwargs)
  File "/opt/airflow/dags/training_pipeline.py", line 184, in train_models
    mlflow.set_experiment(EXPERIMENT_NAME)
  File "/home/airflow/.local/lib/python3.10/site-packages/mlflow/tracking/fluent.py", line 135, in set_experiment
    experiment = client.get_experiment_by_name(experiment_name)
  File "/home/airflow/.local/lib/python3.10/site-packages/mlflow/tracking/client.py", line 520, in get_experiment_by_name
    return self._tracking_client.get_experiment_by_name(name)
  File "/home/airflow/.local/lib/python3.10/site-packages/mlflow/tracking/_tracking_service/client.py", line 221, in get_experiment_by_name
    return self.store.get_experiment_by_name(name)
  File "/home/airflow/.local/lib/python3.10/site-packages/mlflow/store/tracking/rest_store.py", line 306, in get_experiment_by_name
    response_proto = self._call_endpoint(GetExperimentByName, req_body)
  File "/home/airflow/.local/lib/python3.10/site-packages/mlflow/store/tracking/rest_store.py", line 59, in _call_endpoint
    return call_endpoint(self.get_host_creds(), endpoint, method, json_body, response_proto)
  File "/home/airflow/.local/lib/python3.10/site-packages/mlflow/utils/rest_utils.py", line 215, in call_endpoint
    response = http_request(**call_kwargs)
  File "/home/airflow/.local/lib/python3.10/site-packages/mlflow/utils/rest_utils.py", line 129, in http_request
    raise MlflowException(f"API request to {url} failed with exception {e}")
mlflow.exceptions.MlflowException: API request to http://mlflow:5000/api/2.0/mlflow/experiments/get-by-name failed with exception HTTPConnectionPool(host='mlflow', port=5000): Max retries exceeded with url: /api/2.0/mlflow/experiments/get-by-name?experiment_name=forest_cover_classification (Caused by ProtocolError('Connection aborted.', RemoteDisconnected('Remote end closed connection without response')))
[2025-10-06T02:24:12.656+0000] {taskinstance.py:1400} INFO - Marking task as UP_FOR_RETRY. dag_id=forest_cover_training_pipeline, task_id=train_models, execution_date=20251006T021000, start_date=20251006T022008, end_date=20251006T022412
[2025-10-06T02:24:12.682+0000] {standard_task_runner.py:104} ERROR - Failed to execute job 14 for task train_models (API request to http://mlflow:5000/api/2.0/mlflow/experiments/get-by-name failed with exception HTTPConnectionPool(host='mlflow', port=5000): Max retries exceeded with url: /api/2.0/mlflow/experiments/get-by-name?experiment_name=forest_cover_classification (Caused by ProtocolError('Connection aborted.', RemoteDisconnected('Remote end closed connection without response'))); 670)
[2025-10-06T02:24:12.732+0000] {local_task_job_runner.py:228} INFO - Task exited with return code 1
[2025-10-06T02:24:12.770+0000] {taskinstance.py:2778} INFO - 0 downstream tasks scheduled from follow-on schedule check
