[2025-10-06T02:25:14.283+0000] {taskinstance.py:1159} INFO - Dependencies all met for dep_context=non-requeueable deps ti=<TaskInstance: forest_cover_training_pipeline.train_models scheduled__2025-10-06T02:10:00+00:00 [queued]>
[2025-10-06T02:25:14.382+0000] {taskinstance.py:1159} INFO - Dependencies all met for dep_context=requeueable deps ti=<TaskInstance: forest_cover_training_pipeline.train_models scheduled__2025-10-06T02:10:00+00:00 [queued]>
[2025-10-06T02:25:14.382+0000] {taskinstance.py:1361} INFO - Starting attempt 2 of 2
[2025-10-06T02:25:14.389+0000] {taskinstance.py:1382} INFO - Executing <Task(PythonOperator): train_models> on 2025-10-06 02:10:00+00:00
[2025-10-06T02:25:14.395+0000] {standard_task_runner.py:57} INFO - Started process 826 to run task
[2025-10-06T02:25:14.398+0000] {standard_task_runner.py:84} INFO - Running: ['***', 'tasks', 'run', 'forest_cover_training_pipeline', 'train_models', 'scheduled__2025-10-06T02:10:00+00:00', '--job-id', '15', '--raw', '--subdir', 'DAGS_FOLDER/training_pipeline.py', '--cfg-path', '/tmp/tmptkpb79ab']
[2025-10-06T02:25:14.402+0000] {standard_task_runner.py:85} INFO - Job 15: Subtask train_models
[2025-10-06T02:25:14.454+0000] {task_command.py:416} INFO - Running <TaskInstance: forest_cover_training_pipeline.train_models scheduled__2025-10-06T02:10:00+00:00 [running]> on host 2d6451742e7c
[2025-10-06T02:25:14.504+0000] {taskinstance.py:1662} INFO - Exporting env vars: AIRFLOW_CTX_DAG_OWNER='mlops_team' AIRFLOW_CTX_DAG_ID='forest_cover_training_pipeline' AIRFLOW_CTX_TASK_ID='train_models' AIRFLOW_CTX_EXECUTION_DATE='2025-10-06T02:10:00+00:00' AIRFLOW_CTX_TRY_NUMBER='2' AIRFLOW_CTX_DAG_RUN_ID='scheduled__2025-10-06T02:10:00+00:00'
[2025-10-06T02:25:45.348+0000] {connectionpool.py:824} WARNING - Retrying (JitteredRetry(total=4, connect=5, read=4, redirect=5, status=5)) after connection broken by 'ProtocolError('Connection aborted.', RemoteDisconnected('Remote end closed connection without response'))': /api/2.0/mlflow/experiments/get-by-name?experiment_name=forest_cover_classification
[2025-10-06T02:26:20.118+0000] {connectionpool.py:824} WARNING - Retrying (JitteredRetry(total=3, connect=5, read=3, redirect=5, status=5)) after connection broken by 'ProtocolError('Connection aborted.', RemoteDisconnected('Remote end closed connection without response'))': /api/2.0/mlflow/experiments/get-by-name?experiment_name=forest_cover_classification
[2025-10-06T02:26:58.698+0000] {connectionpool.py:824} WARNING - Retrying (JitteredRetry(total=2, connect=5, read=2, redirect=5, status=5)) after connection broken by 'ProtocolError('Connection aborted.', RemoteDisconnected('Remote end closed connection without response'))': /api/2.0/mlflow/experiments/get-by-name?experiment_name=forest_cover_classification
[2025-10-06T02:27:45.241+0000] {connectionpool.py:824} WARNING - Retrying (JitteredRetry(total=1, connect=5, read=1, redirect=5, status=5)) after connection broken by 'ProtocolError('Connection aborted.', RemoteDisconnected('Remote end closed connection without response'))': /api/2.0/mlflow/experiments/get-by-name?experiment_name=forest_cover_classification
[2025-10-06T02:28:00.014+0000] {local_task_job_runner.py:115} ERROR - Received SIGTERM. Terminating subprocesses
[2025-10-06T02:28:00.125+0000] {process_utils.py:131} INFO - Sending 15 to group 826. PIDs of all processes in the group: [826]
[2025-10-06T02:28:00.132+0000] {process_utils.py:86} INFO - Sending the signal 15 to group 826
[2025-10-06T02:28:00.149+0000] {taskinstance.py:1632} ERROR - Received SIGTERM. Terminating subprocesses.
[2025-10-06T02:28:00.173+0000] {taskinstance.py:1937} ERROR - Task failed with exception
Traceback (most recent call last):
  File "/home/airflow/.local/lib/python3.10/site-packages/mlflow/utils/rest_utils.py", line 107, in http_request
    return _get_http_response_with_retries(
  File "/home/airflow/.local/lib/python3.10/site-packages/mlflow/utils/request_utils.py", line 197, in _get_http_response_with_retries
    return session.request(method, url, allow_redirects=allow_redirects, **kwargs)
  File "/home/airflow/.local/lib/python3.10/site-packages/requests/sessions.py", line 589, in request
    resp = self.send(prep, **send_kwargs)
  File "/home/airflow/.local/lib/python3.10/site-packages/requests/sessions.py", line 703, in send
    r = adapter.send(request, **kwargs)
  File "/home/airflow/.local/lib/python3.10/site-packages/requests/adapters.py", line 486, in send
    resp = conn.urlopen(
  File "/home/airflow/.local/lib/python3.10/site-packages/urllib3/connectionpool.py", line 827, in urlopen
    return self.urlopen(
  File "/home/airflow/.local/lib/python3.10/site-packages/urllib3/connectionpool.py", line 827, in urlopen
    return self.urlopen(
  File "/home/airflow/.local/lib/python3.10/site-packages/urllib3/connectionpool.py", line 827, in urlopen
    return self.urlopen(
  [Previous line repeated 1 more time]
  File "/home/airflow/.local/lib/python3.10/site-packages/urllib3/connectionpool.py", line 715, in urlopen
    httplib_response = self._make_request(
  File "/home/airflow/.local/lib/python3.10/site-packages/urllib3/connectionpool.py", line 467, in _make_request
    six.raise_from(e, None)
  File "<string>", line 3, in raise_from
  File "/home/airflow/.local/lib/python3.10/site-packages/urllib3/connectionpool.py", line 462, in _make_request
    httplib_response = conn.getresponse()
  File "/usr/local/lib/python3.10/http/client.py", line 1375, in getresponse
    response.begin()
  File "/usr/local/lib/python3.10/http/client.py", line 318, in begin
    version, status, reason = self._read_status()
  File "/usr/local/lib/python3.10/http/client.py", line 279, in _read_status
    line = str(self.fp.readline(_MAXLINE + 1), "iso-8859-1")
  File "/usr/local/lib/python3.10/socket.py", line 705, in readinto
    return self._sock.recv_into(b)
  File "/home/airflow/.local/lib/python3.10/site-packages/airflow/models/taskinstance.py", line 1634, in signal_handler
    raise AirflowException("Task received SIGTERM signal")
airflow.exceptions.AirflowException: Task received SIGTERM signal

During handling of the above exception, another exception occurred:

Traceback (most recent call last):
  File "/home/airflow/.local/lib/python3.10/site-packages/airflow/operators/python.py", line 192, in execute
    return_value = self.execute_callable()
  File "/home/airflow/.local/lib/python3.10/site-packages/airflow/operators/python.py", line 209, in execute_callable
    return self.python_callable(*self.op_args, **self.op_kwargs)
  File "/opt/airflow/dags/training_pipeline.py", line 184, in train_models
    mlflow.set_experiment(EXPERIMENT_NAME)
  File "/home/airflow/.local/lib/python3.10/site-packages/mlflow/tracking/fluent.py", line 135, in set_experiment
    experiment = client.get_experiment_by_name(experiment_name)
  File "/home/airflow/.local/lib/python3.10/site-packages/mlflow/tracking/client.py", line 520, in get_experiment_by_name
    return self._tracking_client.get_experiment_by_name(name)
  File "/home/airflow/.local/lib/python3.10/site-packages/mlflow/tracking/_tracking_service/client.py", line 221, in get_experiment_by_name
    return self.store.get_experiment_by_name(name)
  File "/home/airflow/.local/lib/python3.10/site-packages/mlflow/store/tracking/rest_store.py", line 306, in get_experiment_by_name
    response_proto = self._call_endpoint(GetExperimentByName, req_body)
  File "/home/airflow/.local/lib/python3.10/site-packages/mlflow/store/tracking/rest_store.py", line 59, in _call_endpoint
    return call_endpoint(self.get_host_creds(), endpoint, method, json_body, response_proto)
  File "/home/airflow/.local/lib/python3.10/site-packages/mlflow/utils/rest_utils.py", line 215, in call_endpoint
    response = http_request(**call_kwargs)
  File "/home/airflow/.local/lib/python3.10/site-packages/mlflow/utils/rest_utils.py", line 129, in http_request
    raise MlflowException(f"API request to {url} failed with exception {e}")
mlflow.exceptions.MlflowException: API request to http://mlflow:5000/api/2.0/mlflow/experiments/get-by-name failed with exception Task received SIGTERM signal
[2025-10-06T02:28:00.327+0000] {taskinstance.py:1400} INFO - Marking task as FAILED. dag_id=forest_cover_training_pipeline, task_id=train_models, execution_date=20251006T021000, start_date=20251006T022514, end_date=20251006T022800
[2025-10-06T02:28:00.369+0000] {standard_task_runner.py:104} ERROR - Failed to execute job 15 for task train_models (API request to http://mlflow:5000/api/2.0/mlflow/experiments/get-by-name failed with exception Task received SIGTERM signal; 826)
[2025-10-06T02:28:00.387+0000] {process_utils.py:79} INFO - Process psutil.Process(pid=826, status='terminated', exitcode=1, started='02:25:13') (826) terminated with exit code 1
[2025-10-06T02:28:00.391+0000] {local_task_job_runner.py:228} INFO - Task exited with return code 143
[2025-10-06T02:28:00.511+0000] {taskinstance.py:2778} INFO - 0 downstream tasks scheduled from follow-on schedule check
