[2025-10-06T03:49:11.757+0000] {taskinstance.py:1159} INFO - Dependencies all met for dep_context=non-requeueable deps ti=<TaskInstance: forest_cover_training_pipeline.preprocess_data scheduled__2025-10-06T03:42:00+00:00 [queued]>
[2025-10-06T03:49:11.762+0000] {taskinstance.py:1159} INFO - Dependencies all met for dep_context=requeueable deps ti=<TaskInstance: forest_cover_training_pipeline.preprocess_data scheduled__2025-10-06T03:42:00+00:00 [queued]>
[2025-10-06T03:49:11.762+0000] {taskinstance.py:1361} INFO - Starting attempt 2 of 2
[2025-10-06T03:49:11.769+0000] {taskinstance.py:1382} INFO - Executing <Task(PythonOperator): preprocess_data> on 2025-10-06 03:42:00+00:00
[2025-10-06T03:49:11.775+0000] {standard_task_runner.py:57} INFO - Started process 3270 to run task
[2025-10-06T03:49:11.778+0000] {standard_task_runner.py:84} INFO - Running: ['***', 'tasks', 'run', 'forest_cover_training_pipeline', 'preprocess_data', 'scheduled__2025-10-06T03:42:00+00:00', '--job-id', '62', '--raw', '--subdir', 'DAGS_FOLDER/training_pipeline.py', '--cfg-path', '/tmp/tmppw3fzvs8']
[2025-10-06T03:49:11.789+0000] {standard_task_runner.py:85} INFO - Job 62: Subtask preprocess_data
[2025-10-06T03:49:11.842+0000] {task_command.py:416} INFO - Running <TaskInstance: forest_cover_training_pipeline.preprocess_data scheduled__2025-10-06T03:42:00+00:00 [running]> on host 20acfc9d0a87
[2025-10-06T03:49:11.923+0000] {taskinstance.py:1662} INFO - Exporting env vars: AIRFLOW_CTX_DAG_OWNER='mlops_team' AIRFLOW_CTX_DAG_ID='forest_cover_training_pipeline' AIRFLOW_CTX_TASK_ID='preprocess_data' AIRFLOW_CTX_EXECUTION_DATE='2025-10-06T03:42:00+00:00' AIRFLOW_CTX_TRY_NUMBER='2' AIRFLOW_CTX_DAG_RUN_ID='scheduled__2025-10-06T03:42:00+00:00'
[2025-10-06T03:49:12.117+0000] {taskinstance.py:1937} ERROR - Task failed with exception
Traceback (most recent call last):
  File "/home/airflow/.local/lib/python3.10/site-packages/sqlalchemy/engine/base.py", line 1910, in _execute_context
    self.dialect.do_execute(
  File "/home/airflow/.local/lib/python3.10/site-packages/sqlalchemy/engine/default.py", line 736, in do_execute
    cursor.execute(statement, parameters)
  File "/home/airflow/.local/lib/python3.10/site-packages/pymysql/cursors.py", line 153, in execute
    result = self._query(query)
  File "/home/airflow/.local/lib/python3.10/site-packages/pymysql/cursors.py", line 322, in _query
    conn.query(q)
  File "/home/airflow/.local/lib/python3.10/site-packages/pymysql/connections.py", line 558, in query
    self._affected_rows = self._read_query_result(unbuffered=unbuffered)
  File "/home/airflow/.local/lib/python3.10/site-packages/pymysql/connections.py", line 822, in _read_query_result
    result.read()
  File "/home/airflow/.local/lib/python3.10/site-packages/pymysql/connections.py", line 1200, in read
    first_packet = self.connection._read_packet()
  File "/home/airflow/.local/lib/python3.10/site-packages/pymysql/connections.py", line 772, in _read_packet
    packet.raise_for_error()
  File "/home/airflow/.local/lib/python3.10/site-packages/pymysql/protocol.py", line 221, in raise_for_error
    err.raise_mysql_exception(self._data)
  File "/home/airflow/.local/lib/python3.10/site-packages/pymysql/err.py", line 143, in raise_mysql_exception
    raise errorclass(errno, errval)
pymysql.err.ProgrammingError: (1146, "Table 'datasets_db.forest_curated' doesn't exist")

The above exception was the direct cause of the following exception:

Traceback (most recent call last):
  File "/home/airflow/.local/lib/python3.10/site-packages/airflow/operators/python.py", line 192, in execute
    return_value = self.execute_callable()
  File "/home/airflow/.local/lib/python3.10/site-packages/airflow/operators/python.py", line 209, in execute_callable
    return self.python_callable(*self.op_args, **self.op_kwargs)
  File "/opt/airflow/dags/training_pipeline.py", line 197, in preprocess_data
    conn.execute(sa.text("DELETE FROM datasets_db.forest_curated WHERE batch = :b"), {"b": int(last_batch)})
  File "/home/airflow/.local/lib/python3.10/site-packages/sqlalchemy/future/engine.py", line 280, in execute
    return self._execute_20(
  File "/home/airflow/.local/lib/python3.10/site-packages/sqlalchemy/engine/base.py", line 1710, in _execute_20
    return meth(self, args_10style, kwargs_10style, execution_options)
  File "/home/airflow/.local/lib/python3.10/site-packages/sqlalchemy/sql/elements.py", line 334, in _execute_on_connection
    return connection._execute_clauseelement(
  File "/home/airflow/.local/lib/python3.10/site-packages/sqlalchemy/engine/base.py", line 1577, in _execute_clauseelement
    ret = self._execute_context(
  File "/home/airflow/.local/lib/python3.10/site-packages/sqlalchemy/engine/base.py", line 1953, in _execute_context
    self._handle_dbapi_exception(
  File "/home/airflow/.local/lib/python3.10/site-packages/sqlalchemy/engine/base.py", line 2134, in _handle_dbapi_exception
    util.raise_(
  File "/home/airflow/.local/lib/python3.10/site-packages/sqlalchemy/util/compat.py", line 211, in raise_
    raise exception
  File "/home/airflow/.local/lib/python3.10/site-packages/sqlalchemy/engine/base.py", line 1910, in _execute_context
    self.dialect.do_execute(
  File "/home/airflow/.local/lib/python3.10/site-packages/sqlalchemy/engine/default.py", line 736, in do_execute
    cursor.execute(statement, parameters)
  File "/home/airflow/.local/lib/python3.10/site-packages/pymysql/cursors.py", line 153, in execute
    result = self._query(query)
  File "/home/airflow/.local/lib/python3.10/site-packages/pymysql/cursors.py", line 322, in _query
    conn.query(q)
  File "/home/airflow/.local/lib/python3.10/site-packages/pymysql/connections.py", line 558, in query
    self._affected_rows = self._read_query_result(unbuffered=unbuffered)
  File "/home/airflow/.local/lib/python3.10/site-packages/pymysql/connections.py", line 822, in _read_query_result
    result.read()
  File "/home/airflow/.local/lib/python3.10/site-packages/pymysql/connections.py", line 1200, in read
    first_packet = self.connection._read_packet()
  File "/home/airflow/.local/lib/python3.10/site-packages/pymysql/connections.py", line 772, in _read_packet
    packet.raise_for_error()
  File "/home/airflow/.local/lib/python3.10/site-packages/pymysql/protocol.py", line 221, in raise_for_error
    err.raise_mysql_exception(self._data)
  File "/home/airflow/.local/lib/python3.10/site-packages/pymysql/err.py", line 143, in raise_mysql_exception
    raise errorclass(errno, errval)
sqlalchemy.exc.ProgrammingError: (pymysql.err.ProgrammingError) (1146, "Table 'datasets_db.forest_curated' doesn't exist")
[SQL: DELETE FROM datasets_db.forest_curated WHERE batch = %(b)s]
[parameters: {'b': 9}]
(Background on this error at: https://sqlalche.me/e/14/f405)
[2025-10-06T03:49:12.126+0000] {taskinstance.py:1400} INFO - Marking task as FAILED. dag_id=forest_cover_training_pipeline, task_id=preprocess_data, execution_date=20251006T034200, start_date=20251006T034911, end_date=20251006T034912
[2025-10-06T03:49:12.135+0000] {standard_task_runner.py:104} ERROR - Failed to execute job 62 for task preprocess_data ((pymysql.err.ProgrammingError) (1146, "Table 'datasets_db.forest_curated' doesn't exist")
[SQL: DELETE FROM datasets_db.forest_curated WHERE batch = %(b)s]
[parameters: {'b': 9}]
(Background on this error at: https://sqlalche.me/e/14/f405); 3270)
[2025-10-06T03:49:12.174+0000] {local_task_job_runner.py:228} INFO - Task exited with return code 1
[2025-10-06T03:49:12.193+0000] {taskinstance.py:2778} INFO - 0 downstream tasks scheduled from follow-on schedule check
