[2025-10-06T03:43:09.341+0000] {taskinstance.py:1159} INFO - Dependencies all met for dep_context=non-requeueable deps ti=<TaskInstance: forest_cover_training_pipeline.fetch_data scheduled__2025-10-06T03:36:00+00:00 [queued]>
[2025-10-06T03:43:09.347+0000] {taskinstance.py:1159} INFO - Dependencies all met for dep_context=requeueable deps ti=<TaskInstance: forest_cover_training_pipeline.fetch_data scheduled__2025-10-06T03:36:00+00:00 [queued]>
[2025-10-06T03:43:09.348+0000] {taskinstance.py:1361} INFO - Starting attempt 2 of 2
[2025-10-06T03:43:09.355+0000] {taskinstance.py:1382} INFO - Executing <Task(PythonOperator): fetch_data> on 2025-10-06 03:36:00+00:00
[2025-10-06T03:43:09.365+0000] {standard_task_runner.py:57} INFO - Started process 2998 to run task
[2025-10-06T03:43:09.372+0000] {standard_task_runner.py:84} INFO - Running: ['***', 'tasks', 'run', 'forest_cover_training_pipeline', 'fetch_data', 'scheduled__2025-10-06T03:36:00+00:00', '--job-id', '53', '--raw', '--subdir', 'DAGS_FOLDER/training_pipeline.py', '--cfg-path', '/tmp/tmplmqthr49']
[2025-10-06T03:43:09.375+0000] {standard_task_runner.py:85} INFO - Job 53: Subtask fetch_data
[2025-10-06T03:43:09.437+0000] {task_command.py:416} INFO - Running <TaskInstance: forest_cover_training_pipeline.fetch_data scheduled__2025-10-06T03:36:00+00:00 [running]> on host 20acfc9d0a87
[2025-10-06T03:43:09.538+0000] {taskinstance.py:1662} INFO - Exporting env vars: AIRFLOW_CTX_DAG_OWNER='mlops_team' AIRFLOW_CTX_DAG_ID='forest_cover_training_pipeline' AIRFLOW_CTX_TASK_ID='fetch_data' AIRFLOW_CTX_EXECUTION_DATE='2025-10-06T03:36:00+00:00' AIRFLOW_CTX_TRY_NUMBER='2' AIRFLOW_CTX_DAG_RUN_ID='scheduled__2025-10-06T03:36:00+00:00'
[2025-10-06T03:43:09.540+0000] {taskinstance.py:1937} ERROR - Task failed with exception
Traceback (most recent call last):
  File "/home/airflow/.local/lib/python3.10/site-packages/airflow/operators/python.py", line 192, in execute
    return_value = self.execute_callable()
  File "/home/airflow/.local/lib/python3.10/site-packages/airflow/operators/python.py", line 209, in execute_callable
    return self.python_callable(*self.op_args, **self.op_kwargs)
  File "/opt/airflow/dags/training_pipeline.py", line 84, in fetch_data_from_api
    batch = int(payload.get('batch_number', -1))
NameError: name 'payload' is not defined
[2025-10-06T03:43:09.549+0000] {taskinstance.py:1400} INFO - Marking task as FAILED. dag_id=forest_cover_training_pipeline, task_id=fetch_data, execution_date=20251006T033600, start_date=20251006T034309, end_date=20251006T034309
[2025-10-06T03:43:09.556+0000] {standard_task_runner.py:104} ERROR - Failed to execute job 53 for task fetch_data (name 'payload' is not defined; 2998)
[2025-10-06T03:43:09.593+0000] {local_task_job_runner.py:228} INFO - Task exited with return code 1
[2025-10-06T03:43:09.610+0000] {taskinstance.py:2778} INFO - 0 downstream tasks scheduled from follow-on schedule check
