[2025-10-05T22:42:45.911+0000] {taskinstance.py:1159} INFO - Dependencies all met for dep_context=non-requeueable deps ti=<TaskInstance: forest_cover_training_pipeline.fetch_data scheduled__2025-10-05T22:20:00+00:00 [queued]>
[2025-10-05T22:42:46.037+0000] {taskinstance.py:1159} INFO - Dependencies all met for dep_context=requeueable deps ti=<TaskInstance: forest_cover_training_pipeline.fetch_data scheduled__2025-10-05T22:20:00+00:00 [queued]>
[2025-10-05T22:42:46.037+0000] {taskinstance.py:1361} INFO - Starting attempt 2 of 2
[2025-10-05T22:42:46.056+0000] {taskinstance.py:1382} INFO - Executing <Task(PythonOperator): fetch_data> on 2025-10-05 22:20:00+00:00
[2025-10-05T22:42:46.066+0000] {standard_task_runner.py:57} INFO - Started process 1118 to run task
[2025-10-05T22:42:46.074+0000] {standard_task_runner.py:84} INFO - Running: ['***', 'tasks', 'run', 'forest_cover_training_pipeline', 'fetch_data', 'scheduled__2025-10-05T22:20:00+00:00', '--job-id', '18', '--raw', '--subdir', 'DAGS_FOLDER/training_pipeline.py', '--cfg-path', '/tmp/tmpifg2ku2v']
[2025-10-05T22:42:46.091+0000] {standard_task_runner.py:85} INFO - Job 18: Subtask fetch_data
[2025-10-05T22:42:46.136+0000] {task_command.py:416} INFO - Running <TaskInstance: forest_cover_training_pipeline.fetch_data scheduled__2025-10-05T22:20:00+00:00 [running]> on host 4c3e0b03c920
[2025-10-05T22:42:46.208+0000] {taskinstance.py:1662} INFO - Exporting env vars: AIRFLOW_CTX_DAG_OWNER='mlops_team' AIRFLOW_CTX_DAG_ID='forest_cover_training_pipeline' AIRFLOW_CTX_TASK_ID='fetch_data' AIRFLOW_CTX_EXECUTION_DATE='2025-10-05T22:20:00+00:00' AIRFLOW_CTX_TRY_NUMBER='2' AIRFLOW_CTX_DAG_RUN_ID='scheduled__2025-10-05T22:20:00+00:00'
[2025-10-05T22:42:56.198+0000] {local_task_job_runner.py:294} WARNING - State of this instance has been externally set to failed. Terminating instance.
[2025-10-05T22:42:56.217+0000] {process_utils.py:131} INFO - Sending 15 to group 1118. PIDs of all processes in the group: [1118]
[2025-10-05T22:42:56.218+0000] {process_utils.py:86} INFO - Sending the signal 15 to group 1118
[2025-10-05T22:42:56.221+0000] {taskinstance.py:1632} ERROR - Received SIGTERM. Terminating subprocesses.
[2025-10-05T22:42:56.275+0000] {process_utils.py:79} INFO - Process psutil.Process(pid=1118, status='terminated', exitcode=0, started='22:42:45') (1118) terminated with exit code 0
