[2025-10-05T22:42:41.824+0000] {taskinstance.py:1159} INFO - Dependencies all met for dep_context=non-requeueable deps ti=<TaskInstance: forest_cover_training_pipeline.fetch_data scheduled__2025-10-05T22:20:00+00:00 [queued]>
[2025-10-05T22:42:42.080+0000] {taskinstance.py:1159} INFO - Dependencies all met for dep_context=requeueable deps ti=<TaskInstance: forest_cover_training_pipeline.fetch_data scheduled__2025-10-05T22:20:00+00:00 [queued]>
[2025-10-05T22:42:42.081+0000] {taskinstance.py:1361} INFO - Starting attempt 1 of 2
[2025-10-05T22:42:42.092+0000] {taskinstance.py:1382} INFO - Executing <Task(PythonOperator): fetch_data> on 2025-10-05 22:20:00+00:00
[2025-10-05T22:42:42.102+0000] {standard_task_runner.py:57} INFO - Started process 1097 to run task
[2025-10-05T22:42:42.110+0000] {standard_task_runner.py:84} INFO - Running: ['***', 'tasks', 'run', 'forest_cover_training_pipeline', 'fetch_data', 'scheduled__2025-10-05T22:20:00+00:00', '--job-id', '15', '--raw', '--subdir', 'DAGS_FOLDER/training_pipeline.py', '--cfg-path', '/tmp/tmp_gudw6r4']
[2025-10-05T22:42:42.114+0000] {standard_task_runner.py:85} INFO - Job 15: Subtask fetch_data
[2025-10-05T22:42:42.159+0000] {task_command.py:416} INFO - Running <TaskInstance: forest_cover_training_pipeline.fetch_data scheduled__2025-10-05T22:20:00+00:00 [running]> on host 4c3e0b03c920
[2025-10-05T22:42:42.218+0000] {taskinstance.py:1662} INFO - Exporting env vars: AIRFLOW_CTX_DAG_OWNER='mlops_team' AIRFLOW_CTX_DAG_ID='forest_cover_training_pipeline' AIRFLOW_CTX_TASK_ID='fetch_data' AIRFLOW_CTX_EXECUTION_DATE='2025-10-05T22:20:00+00:00' AIRFLOW_CTX_TRY_NUMBER='1' AIRFLOW_CTX_DAG_RUN_ID='scheduled__2025-10-05T22:20:00+00:00'
[2025-10-05T22:42:47.218+0000] {local_task_job_runner.py:274} WARNING - Recorded pid 1118 does not match the current pid 1097
[2025-10-05T22:42:47.222+0000] {process_utils.py:131} INFO - Sending 15 to group 1097. PIDs of all processes in the group: [1097]
[2025-10-05T22:42:47.222+0000] {process_utils.py:86} INFO - Sending the signal 15 to group 1097
[2025-10-05T22:42:47.223+0000] {taskinstance.py:1632} ERROR - Received SIGTERM. Terminating subprocesses.
[2025-10-05T22:42:47.255+0000] {taskinstance.py:1937} ERROR - Task failed with exception
Traceback (most recent call last):
  File "/home/airflow/.local/lib/python3.10/site-packages/airflow/operators/python.py", line 192, in execute
    return_value = self.execute_callable()
  File "/home/airflow/.local/lib/python3.10/site-packages/airflow/operators/python.py", line 209, in execute_callable
    return self.python_callable(*self.op_args, **self.op_kwargs)
  File "/opt/airflow/dags/training_pipeline.py", line 59, in fetch_data_from_api
    r = requests.get(DATA_ENDPOINT, params=params, timeout=60)
  File "/home/airflow/.local/lib/python3.10/site-packages/requests/api.py", line 73, in get
    return request("get", url, params=params, **kwargs)
  File "/home/airflow/.local/lib/python3.10/site-packages/requests/api.py", line 59, in request
    return session.request(method=method, url=url, **kwargs)
  File "/home/airflow/.local/lib/python3.10/site-packages/requests/sessions.py", line 589, in request
    resp = self.send(prep, **send_kwargs)
  File "/home/airflow/.local/lib/python3.10/site-packages/requests/sessions.py", line 703, in send
    r = adapter.send(request, **kwargs)
  File "/home/airflow/.local/lib/python3.10/site-packages/requests/adapters.py", line 486, in send
    resp = conn.urlopen(
  File "/home/airflow/.local/lib/python3.10/site-packages/urllib3/connectionpool.py", line 715, in urlopen
    httplib_response = self._make_request(
  File "/home/airflow/.local/lib/python3.10/site-packages/urllib3/connectionpool.py", line 416, in _make_request
    conn.request(method, url, **httplib_request_kw)
  File "/home/airflow/.local/lib/python3.10/site-packages/urllib3/connection.py", line 244, in request
    super(HTTPConnection, self).request(method, url, body=body, headers=headers)
  File "/usr/local/lib/python3.10/http/client.py", line 1283, in request
    self._send_request(method, url, body, headers, encode_chunked)
  File "/usr/local/lib/python3.10/http/client.py", line 1329, in _send_request
    self.endheaders(body, encode_chunked=encode_chunked)
  File "/usr/local/lib/python3.10/http/client.py", line 1278, in endheaders
    self._send_output(message_body, encode_chunked=encode_chunked)
  File "/usr/local/lib/python3.10/http/client.py", line 1038, in _send_output
    self.send(msg)
  File "/usr/local/lib/python3.10/http/client.py", line 976, in send
    self.connect()
  File "/home/airflow/.local/lib/python3.10/site-packages/urllib3/connection.py", line 205, in connect
    conn = self._new_conn()
  File "/home/airflow/.local/lib/python3.10/site-packages/urllib3/connection.py", line 174, in _new_conn
    conn = connection.create_connection(
  File "/home/airflow/.local/lib/python3.10/site-packages/urllib3/util/connection.py", line 85, in create_connection
    sock.connect(sa)
  File "/home/airflow/.local/lib/python3.10/site-packages/airflow/models/taskinstance.py", line 1634, in signal_handler
    raise AirflowException("Task received SIGTERM signal")
airflow.exceptions.AirflowException: Task received SIGTERM signal
[2025-10-05T22:42:47.264+0000] {taskinstance.py:1400} INFO - Marking task as FAILED. dag_id=forest_cover_training_pipeline, task_id=fetch_data, execution_date=20251005T222000, start_date=20251005T224245, end_date=20251005T224247
[2025-10-05T22:42:47.297+0000] {standard_task_runner.py:104} ERROR - Failed to execute job 15 for task fetch_data (Task received SIGTERM signal; 1097)
[2025-10-05T22:42:47.323+0000] {process_utils.py:79} INFO - Process psutil.Process(pid=1097, status='terminated', exitcode=1, started='22:42:41') (1097) terminated with exit code 1
