[2025-10-06T02:30:27.898+0000] {taskinstance.py:1159} INFO - Dependencies all met for dep_context=non-requeueable deps ti=<TaskInstance: forest_cover_training_pipeline.preprocess_data manual__2025-10-06T02:30:19.323911+00:00 [queued]>
[2025-10-06T02:30:28.052+0000] {taskinstance.py:1159} INFO - Dependencies all met for dep_context=requeueable deps ti=<TaskInstance: forest_cover_training_pipeline.preprocess_data manual__2025-10-06T02:30:19.323911+00:00 [queued]>
[2025-10-06T02:30:28.053+0000] {taskinstance.py:1361} INFO - Starting attempt 1 of 2
[2025-10-06T02:30:28.060+0000] {taskinstance.py:1382} INFO - Executing <Task(PythonOperator): preprocess_data> on 2025-10-06 02:30:19.323911+00:00
[2025-10-06T02:30:28.078+0000] {standard_task_runner.py:57} INFO - Started process 248 to run task
[2025-10-06T02:30:28.097+0000] {standard_task_runner.py:84} INFO - Running: ['***', 'tasks', 'run', 'forest_cover_training_pipeline', 'preprocess_data', 'manual__2025-10-06T02:30:19.323911+00:00', '--job-id', '6', '--raw', '--subdir', 'DAGS_FOLDER/training_pipeline.py', '--cfg-path', '/tmp/tmp_i6604pc']
[2025-10-06T02:30:28.116+0000] {standard_task_runner.py:85} INFO - Job 6: Subtask preprocess_data
[2025-10-06T02:30:28.212+0000] {task_command.py:416} INFO - Running <TaskInstance: forest_cover_training_pipeline.preprocess_data manual__2025-10-06T02:30:19.323911+00:00 [running]> on host 20acfc9d0a87
[2025-10-06T02:30:28.269+0000] {taskinstance.py:1662} INFO - Exporting env vars: AIRFLOW_CTX_DAG_OWNER='mlops_team' AIRFLOW_CTX_DAG_ID='forest_cover_training_pipeline' AIRFLOW_CTX_TASK_ID='preprocess_data' AIRFLOW_CTX_EXECUTION_DATE='2025-10-06T02:30:19.323911+00:00' AIRFLOW_CTX_TRY_NUMBER='1' AIRFLOW_CTX_DAG_RUN_ID='manual__2025-10-06T02:30:19.323911+00:00'
[2025-10-06T02:30:29.201+0000] {taskinstance.py:1937} ERROR - Task failed with exception
Traceback (most recent call last):
  File "/home/airflow/.local/lib/python3.10/site-packages/sqlalchemy/engine/base.py", line 1890, in _execute_context
    self.dialect.do_executemany(
  File "/home/airflow/.local/lib/python3.10/site-packages/sqlalchemy/dialects/mysql/mysqldb.py", line 183, in do_executemany
    rowcount = cursor.executemany(statement, parameters)
  File "/home/airflow/.local/lib/python3.10/site-packages/pymysql/cursors.py", line 182, in executemany
    return self._do_execute_many(
  File "/home/airflow/.local/lib/python3.10/site-packages/pymysql/cursors.py", line 215, in _do_execute_many
    rows += self.execute(sql + postfix)
  File "/home/airflow/.local/lib/python3.10/site-packages/pymysql/cursors.py", line 153, in execute
    result = self._query(query)
  File "/home/airflow/.local/lib/python3.10/site-packages/pymysql/cursors.py", line 322, in _query
    conn.query(q)
  File "/home/airflow/.local/lib/python3.10/site-packages/pymysql/connections.py", line 558, in query
    self._affected_rows = self._read_query_result(unbuffered=unbuffered)
  File "/home/airflow/.local/lib/python3.10/site-packages/pymysql/connections.py", line 822, in _read_query_result
    result.read()
  File "/home/airflow/.local/lib/python3.10/site-packages/pymysql/connections.py", line 1200, in read
    first_packet = self.connection._read_packet()
  File "/home/airflow/.local/lib/python3.10/site-packages/pymysql/connections.py", line 772, in _read_packet
    packet.raise_for_error()
  File "/home/airflow/.local/lib/python3.10/site-packages/pymysql/protocol.py", line 221, in raise_for_error
    err.raise_mysql_exception(self._data)
  File "/home/airflow/.local/lib/python3.10/site-packages/pymysql/err.py", line 143, in raise_mysql_exception
    raise errorclass(errno, errval)
pymysql.err.OperationalError: (1213, 'Deadlock found when trying to get lock; try restarting transaction')

The above exception was the direct cause of the following exception:

Traceback (most recent call last):
  File "/home/airflow/.local/lib/python3.10/site-packages/airflow/operators/python.py", line 192, in execute
    return_value = self.execute_callable()
  File "/home/airflow/.local/lib/python3.10/site-packages/airflow/operators/python.py", line 209, in execute_callable
    return self.python_callable(*self.op_args, **self.op_kwargs)
  File "/opt/airflow/dags/training_pipeline.py", line 148, in preprocess_data
    curated.to_sql('forest_curated', con=conn, schema='datasets_db', if_exists='append', index=False)
  File "/home/airflow/.local/lib/python3.10/site-packages/pandas/util/_decorators.py", line 333, in wrapper
    return func(*args, **kwargs)
  File "/home/airflow/.local/lib/python3.10/site-packages/pandas/core/generic.py", line 3008, in to_sql
    return sql.to_sql(
  File "/home/airflow/.local/lib/python3.10/site-packages/pandas/io/sql.py", line 788, in to_sql
    return pandas_sql.to_sql(
  File "/home/airflow/.local/lib/python3.10/site-packages/pandas/io/sql.py", line 1958, in to_sql
    total_inserted = sql_engine.insert_records(
  File "/home/airflow/.local/lib/python3.10/site-packages/pandas/io/sql.py", line 1507, in insert_records
    raise err
  File "/home/airflow/.local/lib/python3.10/site-packages/pandas/io/sql.py", line 1498, in insert_records
    return table.insert(chunksize=chunksize, method=method)
  File "/home/airflow/.local/lib/python3.10/site-packages/pandas/io/sql.py", line 1059, in insert
    num_inserted = exec_insert(conn, keys, chunk_iter)
  File "/home/airflow/.local/lib/python3.10/site-packages/pandas/io/sql.py", line 951, in _execute_insert
    result = conn.execute(self.table.insert(), data)
  File "/home/airflow/.local/lib/python3.10/site-packages/sqlalchemy/future/engine.py", line 280, in execute
    return self._execute_20(
  File "/home/airflow/.local/lib/python3.10/site-packages/sqlalchemy/engine/base.py", line 1710, in _execute_20
    return meth(self, args_10style, kwargs_10style, execution_options)
  File "/home/airflow/.local/lib/python3.10/site-packages/sqlalchemy/sql/elements.py", line 334, in _execute_on_connection
    return connection._execute_clauseelement(
  File "/home/airflow/.local/lib/python3.10/site-packages/sqlalchemy/engine/base.py", line 1577, in _execute_clauseelement
    ret = self._execute_context(
  File "/home/airflow/.local/lib/python3.10/site-packages/sqlalchemy/engine/base.py", line 1953, in _execute_context
    self._handle_dbapi_exception(
  File "/home/airflow/.local/lib/python3.10/site-packages/sqlalchemy/engine/base.py", line 2134, in _handle_dbapi_exception
    util.raise_(
  File "/home/airflow/.local/lib/python3.10/site-packages/sqlalchemy/util/compat.py", line 211, in raise_
    raise exception
  File "/home/airflow/.local/lib/python3.10/site-packages/sqlalchemy/engine/base.py", line 1890, in _execute_context
    self.dialect.do_executemany(
  File "/home/airflow/.local/lib/python3.10/site-packages/sqlalchemy/dialects/mysql/mysqldb.py", line 183, in do_executemany
    rowcount = cursor.executemany(statement, parameters)
  File "/home/airflow/.local/lib/python3.10/site-packages/pymysql/cursors.py", line 182, in executemany
    return self._do_execute_many(
  File "/home/airflow/.local/lib/python3.10/site-packages/pymysql/cursors.py", line 215, in _do_execute_many
    rows += self.execute(sql + postfix)
  File "/home/airflow/.local/lib/python3.10/site-packages/pymysql/cursors.py", line 153, in execute
    result = self._query(query)
  File "/home/airflow/.local/lib/python3.10/site-packages/pymysql/cursors.py", line 322, in _query
    conn.query(q)
  File "/home/airflow/.local/lib/python3.10/site-packages/pymysql/connections.py", line 558, in query
    self._affected_rows = self._read_query_result(unbuffered=unbuffered)
  File "/home/airflow/.local/lib/python3.10/site-packages/pymysql/connections.py", line 822, in _read_query_result
    result.read()
  File "/home/airflow/.local/lib/python3.10/site-packages/pymysql/connections.py", line 1200, in read
    first_packet = self.connection._read_packet()
  File "/home/airflow/.local/lib/python3.10/site-packages/pymysql/connections.py", line 772, in _read_packet
    packet.raise_for_error()
  File "/home/airflow/.local/lib/python3.10/site-packages/pymysql/protocol.py", line 221, in raise_for_error
    err.raise_mysql_exception(self._data)
  File "/home/airflow/.local/lib/python3.10/site-packages/pymysql/err.py", line 143, in raise_mysql_exception
    raise errorclass(errno, errval)
sqlalchemy.exc.OperationalError: (pymysql.err.OperationalError) (1213, 'Deadlock found when trying to get lock; try restarting transaction')
[SQL: INSERT INTO datasets_db.forest_curated (id, `Elevation`, `Aspect`, `Slope`, `Horizontal_Distance_To_Hydrology`, `Vertical_Distance_To_Hydrology`, `Horizontal_Distance_To_Roadways`, `Hillshade_9am`, `Hillshade_Noon`, `Hillshade_3pm`, `Horizontal_Distance_To_Fire_Points`, `Wilderness_Area`, `Soil_Type`, `Cover_Type`, batch, processed_at) VALUES (%(id)s, %(Elevation)s, %(Aspect)s, %(Slope)s, %(Horizontal_Distance_To_Hydrology)s, %(Vertical_Distance_To_Hydrology)s, %(Horizontal_Distance_To_Roadways)s, %(Hillshade_9am)s, %(Hillshade_Noon)s, %(Hillshade_3pm)s, %(Horizontal_Distance_To_Fire_Points)s, %(Wilderness_Area)s, %(Soil_Type)s, %(Cover_Type)s, %(batch)s, %(processed_at)s)]
[parameters: ({'id': 1, 'Elevation': 2481.0, 'Aspect': 316.0, 'Slope': 26.0, 'Horizontal_Distance_To_Hydrology': 42.0, 'Vertical_Distance_To_Hydrology': 17.0, 'Horizontal_Distance_To_Roadways': 792.0, 'Hillshade_9am': 143, 'Hillshade_Noon': 209, 'Hillshade_3pm': 201, 'Horizontal_Distance_To_Fire_Points': 618.0, 'Wilderness_Area': 'Commanche', 'Soil_Type': 'C4703', 'Cover_Type': 5, 'batch': 5, 'processed_at': datetime.datetime(2025, 10, 6, 2, 30, 28, 582426, tzinfo=datetime.timezone.utc)}, {'id': 2, 'Elevation': 3076.0, 'Aspect': 67.0, 'Slope': 14.0, 'Horizontal_Distance_To_Hydrology': 90.0, 'Vertical_Distance_To_Hydrology': -21.0, 'Horizontal_Distance_To_Roadways': 2708.0, 'Hillshade_9am': 233, 'Hillshade_Noon': 212, 'Hillshade_3pm': 109, 'Horizontal_Distance_To_Fire_Points': 1994.0, 'Wilderness_Area': 'Commanche', 'Soil_Type': 'C7755', 'Cover_Type': 0, 'batch': 5, 'processed_at': datetime.datetime(2025, 10, 6, 2, 30, 28, 582426, tzinfo=datetime.timezone.utc)}, {'id': 3, 'Elevation': 3222.0, 'Aspect': 357.0, 'Slope': 13.0, 'Horizontal_Distance_To_Hydrology': 150.0, 'Vertical_Distance_To_Hydrology': 57.0, 'Horizontal_Distance_To_Roadways': 3412.0, 'Hillshade_9am': 199, 'Hillshade_Noon': 216, 'Hillshade_3pm': 154, 'Horizontal_Distance_To_Fire_Points': 2522.0, 'Wilderness_Area': 'Commanche', 'Soil_Type': 'C7755', 'Cover_Type': 0, 'batch': 5, 'processed_at': datetime.datetime(2025, 10, 6, 2, 30, 28, 582426, tzinfo=datetime.timezone.utc)}, {'id': 4, 'Elevation': 2696.0, 'Aspect': 233.0, 'Slope': 23.0, 'Horizontal_Distance_To_Hydrology': 30.0, 'Vertical_Distance_To_Hydrology': 7.0, 'Horizontal_Distance_To_Roadways': 1928.0, 'Hillshade_9am': 177, 'Hillshade_Noon': 253, 'Hillshade_3pm': 207, 'Horizontal_Distance_To_Fire_Points': 1041.0, 'Wilderness_Area': 'Commanche', 'Soil_Type': 'C7202', 'Cover_Type': 1, 'batch': 5, 'processed_at': datetime.datetime(2025, 10, 6, 2, 30, 28, 582426, tzinfo=datetime.timezone.utc)}, {'id': 5, 'Elevation': 2506.0, 'Aspect': 57.0, 'Slope': 16.0, 'Horizontal_Distance_To_Hydrology': 67.0, 'Vertical_Distance_To_Hydrology': 17.0, 'Horizontal_Distance_To_Roadways': 270.0, 'Hillshade_9am': 229, 'Hillshade_Noon': 204, 'Hillshade_3pm': 103, 'Horizontal_Distance_To_Fire_Points': 1356.0, 'Wilderness_Area': 'Commanche', 'Soil_Type': 'C4703', 'Cover_Type': 2, 'batch': 5, 'processed_at': datetime.datetime(2025, 10, 6, 2, 30, 28, 582426, tzinfo=datetime.timezone.utc)}, {'id': 6, 'Elevation': 3290.0, 'Aspect': 201.0, 'Slope': 19.0, 'Horizontal_Distance_To_Hydrology': 242.0, 'Vertical_Distance_To_Hydrology': 73.0, 'Horizontal_Distance_To_Roadways': 3294.0, 'Hillshade_9am': 209, 'Hillshade_Noon': 253, 'Hillshade_3pm': 172, 'Horizontal_Distance_To_Fire_Points': 618.0, 'Wilderness_Area': 'Commanche', 'Soil_Type': 'C7757', 'Cover_Type': 0, 'batch': 5, 'processed_at': datetime.datetime(2025, 10, 6, 2, 30, 28, 582426, tzinfo=datetime.timezone.utc)}, {'id': 7, 'Elevation': 3383.0, 'Aspect': 307.0, 'Slope': 12.0, 'Horizontal_Distance_To_Hydrology': 541.0, 'Vertical_Distance_To_Hydrology': 44.0, 'Horizontal_Distance_To_Roadways': 1471.0, 'Hillshade_9am': 187, 'Hillshade_Noon': 233, 'Hillshade_3pm': 186, 'Horizontal_Distance_To_Fire_Points': 1024.0, 'Wilderness_Area': 'Commanche', 'Soil_Type': 'C8771', 'Cover_Type': 6, 'batch': 5, 'processed_at': datetime.datetime(2025, 10, 6, 2, 30, 28, 582426, tzinfo=datetime.timezone.utc)}, {'id': 8, 'Elevation': 3000.0, 'Aspect': 332.0, 'Slope': 15.0, 'Horizontal_Distance_To_Hydrology': 212.0, 'Vertical_Distance_To_Hydrology': 28.0, 'Horizontal_Distance_To_Roadways': 2753.0, 'Hillshade_9am': 185, 'Hillshade_Noon': 221, 'Hillshade_3pm': 174, 'Horizontal_Distance_To_Fire_Points': 646.0, 'Wilderness_Area': 'Commanche', 'Soil_Type': 'C7756', 'Cover_Type': 0, 'batch': 5, 'processed_at': datetime.datetime(2025, 10, 6, 2, 30, 28, 582426, tzinfo=datetime.timezone.utc)}  ... displaying 10 of 11620 total bound parameter sets ...  {'id': 11619, 'Elevation': 3191.0, 'Aspect': 350.0, 'Slope': 12.0, 'Horizontal_Distance_To_Hydrology': 514.0, 'Vertical_Distance_To_Hydrology': 95.0, 'Horizontal_Distance_To_Roadways': 1627.0, 'Hillshade_9am': 198, 'Hillshade_Noon': 219, 'Hillshade_3pm': 160, 'Horizontal_Distance_To_Fire_Points': 2584.0, 'Wilderness_Area': 'Commanche', 'Soil_Type': 'C7757', 'Cover_Type': 0, 'batch': 5, 'processed_at': datetime.datetime(2025, 10, 6, 2, 30, 28, 582426, tzinfo=datetime.timezone.utc)}, {'id': 11620, 'Elevation': 2633.0, 'Aspect': 105.0, 'Slope': 16.0, 'Horizontal_Distance_To_Hydrology': 240.0, 'Vertical_Distance_To_Hydrology': 49.0, 'Horizontal_Distance_To_Roadways': 1634.0, 'Hillshade_9am': 246, 'Hillshade_Noon': 218, 'Hillshade_3pm': 96, 'Horizontal_Distance_To_Fire_Points': 2509.0, 'Wilderness_Area': 'Commanche', 'Soil_Type': 'C2705', 'Cover_Type': 2, 'batch': 5, 'processed_at': datetime.datetime(2025, 10, 6, 2, 30, 28, 582426, tzinfo=datetime.timezone.utc)})]
(Background on this error at: https://sqlalche.me/e/14/e3q8)
[2025-10-06T02:30:29.301+0000] {taskinstance.py:1400} INFO - Marking task as UP_FOR_RETRY. dag_id=forest_cover_training_pipeline, task_id=preprocess_data, execution_date=20251006T023019, start_date=20251006T023027, end_date=20251006T023029
[2025-10-06T02:30:29.333+0000] {standard_task_runner.py:104} ERROR - Failed to execute job 6 for task preprocess_data ((pymysql.err.OperationalError) (1213, 'Deadlock found when trying to get lock; try restarting transaction')
[SQL: INSERT INTO datasets_db.forest_curated (id, `Elevation`, `Aspect`, `Slope`, `Horizontal_Distance_To_Hydrology`, `Vertical_Distance_To_Hydrology`, `Horizontal_Distance_To_Roadways`, `Hillshade_9am`, `Hillshade_Noon`, `Hillshade_3pm`, `Horizontal_Distance_To_Fire_Points`, `Wilderness_Area`, `Soil_Type`, `Cover_Type`, batch, processed_at) VALUES (%(id)s, %(Elevation)s, %(Aspect)s, %(Slope)s, %(Horizontal_Distance_To_Hydrology)s, %(Vertical_Distance_To_Hydrology)s, %(Horizontal_Distance_To_Roadways)s, %(Hillshade_9am)s, %(Hillshade_Noon)s, %(Hillshade_3pm)s, %(Horizontal_Distance_To_Fire_Points)s, %(Wilderness_Area)s, %(Soil_Type)s, %(Cover_Type)s, %(batch)s, %(processed_at)s)]
[parameters: ({'id': 1, 'Elevation': 2481.0, 'Aspect': 316.0, 'Slope': 26.0, 'Horizontal_Distance_To_Hydrology': 42.0, 'Vertical_Distance_To_Hydrology': 17.0, 'Horizontal_Distance_To_Roadways': 792.0, 'Hillshade_9am': 143, 'Hillshade_Noon': 209, 'Hillshade_3pm': 201, 'Horizontal_Distance_To_Fire_Points': 618.0, 'Wilderness_Area': 'Commanche', 'Soil_Type': 'C4703', 'Cover_Type': 5, 'batch': 5, 'processed_at': datetime.datetime(2025, 10, 6, 2, 30, 28, 582426, tzinfo=datetime.timezone.utc)}, {'id': 2, 'Elevation': 3076.0, 'Aspect': 67.0, 'Slope': 14.0, 'Horizontal_Distance_To_Hydrology': 90.0, 'Vertical_Distance_To_Hydrology': -21.0, 'Horizontal_Distance_To_Roadways': 2708.0, 'Hillshade_9am': 233, 'Hillshade_Noon': 212, 'Hillshade_3pm': 109, 'Horizontal_Distance_To_Fire_Points': 1994.0, 'Wilderness_Area': 'Commanche', 'Soil_Type': 'C7755', 'Cover_Type': 0, 'batch': 5, 'processed_at': datetime.datetime(2025, 10, 6, 2, 30, 28, 582426, tzinfo=datetime.timezone.utc)}, {'id': 3, 'Elevation': 3222.0, 'Aspect': 357.0, 'Slope': 13.0, 'Horizontal_Distance_To_Hydrology': 150.0, 'Vertical_Distance_To_Hydrology': 57.0, 'Horizontal_Distance_To_Roadways': 3412.0, 'Hillshade_9am': 199, 'Hillshade_Noon': 216, 'Hillshade_3pm': 154, 'Horizontal_Distance_To_Fire_Points': 2522.0, 'Wilderness_Area': 'Commanche', 'Soil_Type': 'C7755', 'Cover_Type': 0, 'batch': 5, 'processed_at': datetime.datetime(2025, 10, 6, 2, 30, 28, 582426, tzinfo=datetime.timezone.utc)}, {'id': 4, 'Elevation': 2696.0, 'Aspect': 233.0, 'Slope': 23.0, 'Horizontal_Distance_To_Hydrology': 30.0, 'Vertical_Distance_To_Hydrology': 7.0, 'Horizontal_Distance_To_Roadways': 1928.0, 'Hillshade_9am': 177, 'Hillshade_Noon': 253, 'Hillshade_3pm': 207, 'Horizontal_Distance_To_Fire_Points': 1041.0, 'Wilderness_Area': 'Commanche', 'Soil_Type': 'C7202', 'Cover_Type': 1, 'batch': 5, 'processed_at': datetime.datetime(2025, 10, 6, 2, 30, 28, 582426, tzinfo=datetime.timezone.utc)}, {'id': 5, 'Elevation': 2506.0, 'Aspect': 57.0, 'Slope': 16.0, 'Horizontal_Distance_To_Hydrology': 67.0, 'Vertical_Distance_To_Hydrology': 17.0, 'Horizontal_Distance_To_Roadways': 270.0, 'Hillshade_9am': 229, 'Hillshade_Noon': 204, 'Hillshade_3pm': 103, 'Horizontal_Distance_To_Fire_Points': 1356.0, 'Wilderness_Area': 'Commanche', 'Soil_Type': 'C4703', 'Cover_Type': 2, 'batch': 5, 'processed_at': datetime.datetime(2025, 10, 6, 2, 30, 28, 582426, tzinfo=datetime.timezone.utc)}, {'id': 6, 'Elevation': 3290.0, 'Aspect': 201.0, 'Slope': 19.0, 'Horizontal_Distance_To_Hydrology': 242.0, 'Vertical_Distance_To_Hydrology': 73.0, 'Horizontal_Distance_To_Roadways': 3294.0, 'Hillshade_9am': 209, 'Hillshade_Noon': 253, 'Hillshade_3pm': 172, 'Horizontal_Distance_To_Fire_Points': 618.0, 'Wilderness_Area': 'Commanche', 'Soil_Type': 'C7757', 'Cover_Type': 0, 'batch': 5, 'processed_at': datetime.datetime(2025, 10, 6, 2, 30, 28, 582426, tzinfo=datetime.timezone.utc)}, {'id': 7, 'Elevation': 3383.0, 'Aspect': 307.0, 'Slope': 12.0, 'Horizontal_Distance_To_Hydrology': 541.0, 'Vertical_Distance_To_Hydrology': 44.0, 'Horizontal_Distance_To_Roadways': 1471.0, 'Hillshade_9am': 187, 'Hillshade_Noon': 233, 'Hillshade_3pm': 186, 'Horizontal_Distance_To_Fire_Points': 1024.0, 'Wilderness_Area': 'Commanche', 'Soil_Type': 'C8771', 'Cover_Type': 6, 'batch': 5, 'processed_at': datetime.datetime(2025, 10, 6, 2, 30, 28, 582426, tzinfo=datetime.timezone.utc)}, {'id': 8, 'Elevation': 3000.0, 'Aspect': 332.0, 'Slope': 15.0, 'Horizontal_Distance_To_Hydrology': 212.0, 'Vertical_Distance_To_Hydrology': 28.0, 'Horizontal_Distance_To_Roadways': 2753.0, 'Hillshade_9am': 185, 'Hillshade_Noon': 221, 'Hillshade_3pm': 174, 'Horizontal_Distance_To_Fire_Points': 646.0, 'Wilderness_Area': 'Commanche', 'Soil_Type': 'C7756', 'Cover_Type': 0, 'batch': 5, 'processed_at': datetime.datetime(2025, 10, 6, 2, 30, 28, 582426, tzinfo=datetime.timezone.utc)}  ... displaying 10 of 11620 total bound parameter sets ...  {'id': 11619, 'Elevation': 3191.0, 'Aspect': 350.0, 'Slope': 12.0, 'Horizontal_Distance_To_Hydrology': 514.0, 'Vertical_Distance_To_Hydrology': 95.0, 'Horizontal_Distance_To_Roadways': 1627.0, 'Hillshade_9am': 198, 'Hillshade_Noon': 219, 'Hillshade_3pm': 160, 'Horizontal_Distance_To_Fire_Points': 2584.0, 'Wilderness_Area': 'Commanche', 'Soil_Type': 'C7757', 'Cover_Type': 0, 'batch': 5, 'processed_at': datetime.datetime(2025, 10, 6, 2, 30, 28, 582426, tzinfo=datetime.timezone.utc)}, {'id': 11620, 'Elevation': 2633.0, 'Aspect': 105.0, 'Slope': 16.0, 'Horizontal_Distance_To_Hydrology': 240.0, 'Vertical_Distance_To_Hydrology': 49.0, 'Horizontal_Distance_To_Roadways': 1634.0, 'Hillshade_9am': 246, 'Hillshade_Noon': 218, 'Hillshade_3pm': 96, 'Horizontal_Distance_To_Fire_Points': 2509.0, 'Wilderness_Area': 'Commanche', 'Soil_Type': 'C2705', 'Cover_Type': 2, 'batch': 5, 'processed_at': datetime.datetime(2025, 10, 6, 2, 30, 28, 582426, tzinfo=datetime.timezone.utc)})]
(Background on this error at: https://sqlalche.me/e/14/e3q8); 248)
[2025-10-06T02:30:29.398+0000] {local_task_job_runner.py:228} INFO - Task exited with return code 1
[2025-10-06T02:30:29.447+0000] {taskinstance.py:2778} INFO - 0 downstream tasks scheduled from follow-on schedule check
