[2025-10-06T03:54:06.300+0000] {taskinstance.py:1159} INFO - Dependencies all met for dep_context=non-requeueable deps ti=<TaskInstance: forest_cover_training_pipeline.preprocess_data scheduled__2025-10-06T03:48:00+00:00 [queued]>
[2025-10-06T03:54:06.305+0000] {taskinstance.py:1159} INFO - Dependencies all met for dep_context=requeueable deps ti=<TaskInstance: forest_cover_training_pipeline.preprocess_data scheduled__2025-10-06T03:48:00+00:00 [queued]>
[2025-10-06T03:54:06.305+0000] {taskinstance.py:1361} INFO - Starting attempt 1 of 2
[2025-10-06T03:54:06.312+0000] {taskinstance.py:1382} INFO - Executing <Task(PythonOperator): preprocess_data> on 2025-10-06 03:48:00+00:00
[2025-10-06T03:54:06.321+0000] {standard_task_runner.py:57} INFO - Started process 3430 to run task
[2025-10-06T03:54:06.332+0000] {standard_task_runner.py:84} INFO - Running: ['***', 'tasks', 'run', 'forest_cover_training_pipeline', 'preprocess_data', 'scheduled__2025-10-06T03:48:00+00:00', '--job-id', '65', '--raw', '--subdir', 'DAGS_FOLDER/training_pipeline.py', '--cfg-path', '/tmp/tmplvnraags']
[2025-10-06T03:54:06.337+0000] {standard_task_runner.py:85} INFO - Job 65: Subtask preprocess_data
[2025-10-06T03:54:06.379+0000] {task_command.py:416} INFO - Running <TaskInstance: forest_cover_training_pipeline.preprocess_data scheduled__2025-10-06T03:48:00+00:00 [running]> on host 20acfc9d0a87
[2025-10-06T03:54:06.432+0000] {taskinstance.py:1662} INFO - Exporting env vars: AIRFLOW_CTX_DAG_OWNER='mlops_team' AIRFLOW_CTX_DAG_ID='forest_cover_training_pipeline' AIRFLOW_CTX_TASK_ID='preprocess_data' AIRFLOW_CTX_EXECUTION_DATE='2025-10-06T03:48:00+00:00' AIRFLOW_CTX_TRY_NUMBER='1' AIRFLOW_CTX_DAG_RUN_ID='scheduled__2025-10-06T03:48:00+00:00'
[2025-10-06T03:54:06.579+0000] {taskinstance.py:1937} ERROR - Task failed with exception
Traceback (most recent call last):
  File "/home/airflow/.local/lib/python3.10/site-packages/airflow/operators/python.py", line 192, in execute
    return_value = self.execute_callable()
  File "/home/airflow/.local/lib/python3.10/site-packages/airflow/operators/python.py", line 209, in execute_callable
    return self.python_callable(*self.op_args, **self.op_kwargs)
  File "/opt/airflow/dags/training_pipeline.py", line 189, in preprocess_data
    raw = raw.dropna(subset=[
  File "/home/airflow/.local/lib/python3.10/site-packages/pandas/core/frame.py", line 6418, in dropna
    raise KeyError(np.array(subset)[check].tolist())
KeyError: ['Vertical_Distance_To_VHydrology']
[2025-10-06T03:54:06.593+0000] {taskinstance.py:1400} INFO - Marking task as UP_FOR_RETRY. dag_id=forest_cover_training_pipeline, task_id=preprocess_data, execution_date=20251006T034800, start_date=20251006T035406, end_date=20251006T035406
[2025-10-06T03:54:06.600+0000] {standard_task_runner.py:104} ERROR - Failed to execute job 65 for task preprocess_data (['Vertical_Distance_To_VHydrology']; 3430)
[2025-10-06T03:54:06.637+0000] {local_task_job_runner.py:228} INFO - Task exited with return code 1
[2025-10-06T03:54:06.654+0000] {taskinstance.py:2778} INFO - 0 downstream tasks scheduled from follow-on schedule check
