[2025-10-06T02:00:24.939+0000] {taskinstance.py:1159} INFO - Dependencies all met for dep_context=non-requeueable deps ti=<TaskInstance: forest_cover_training_pipeline.api_healthcheck scheduled__2025-10-06T01:50:00+00:00 [queued]>
[2025-10-06T02:00:25.158+0000] {taskinstance.py:1159} INFO - Dependencies all met for dep_context=requeueable deps ti=<TaskInstance: forest_cover_training_pipeline.api_healthcheck scheduled__2025-10-06T01:50:00+00:00 [queued]>
[2025-10-06T02:00:25.159+0000] {taskinstance.py:1361} INFO - Starting attempt 1 of 2
[2025-10-06T02:00:25.172+0000] {taskinstance.py:1382} INFO - Executing <Task(PythonOperator): api_healthcheck> on 2025-10-06 01:50:00+00:00
[2025-10-06T02:00:25.185+0000] {standard_task_runner.py:57} INFO - Started process 4313 to run task
[2025-10-06T02:00:25.194+0000] {standard_task_runner.py:84} INFO - Running: ['***', 'tasks', 'run', 'forest_cover_training_pipeline', 'api_healthcheck', 'scheduled__2025-10-06T01:50:00+00:00', '--job-id', '70', '--raw', '--subdir', 'DAGS_FOLDER/training_pipeline.py', '--cfg-path', '/tmp/tmpohai3jj1']
[2025-10-06T02:00:25.203+0000] {standard_task_runner.py:85} INFO - Job 70: Subtask api_healthcheck
[2025-10-06T02:00:25.310+0000] {task_command.py:416} INFO - Running <TaskInstance: forest_cover_training_pipeline.api_healthcheck scheduled__2025-10-06T01:50:00+00:00 [running]> on host 4c3e0b03c920
[2025-10-06T02:00:25.418+0000] {taskinstance.py:1662} INFO - Exporting env vars: AIRFLOW_CTX_DAG_OWNER='mlops_team' AIRFLOW_CTX_DAG_ID='forest_cover_training_pipeline' AIRFLOW_CTX_TASK_ID='api_healthcheck' AIRFLOW_CTX_EXECUTION_DATE='2025-10-06T01:50:00+00:00' AIRFLOW_CTX_TRY_NUMBER='1' AIRFLOW_CTX_DAG_RUN_ID='scheduled__2025-10-06T01:50:00+00:00'
[2025-10-06T02:00:25.469+0000] {taskinstance.py:1937} ERROR - Task failed with exception
Traceback (most recent call last):
  File "/home/airflow/.local/lib/python3.10/site-packages/urllib3/connectionpool.py", line 715, in urlopen
    httplib_response = self._make_request(
  File "/home/airflow/.local/lib/python3.10/site-packages/urllib3/connectionpool.py", line 467, in _make_request
    six.raise_from(e, None)
  File "<string>", line 3, in raise_from
  File "/home/airflow/.local/lib/python3.10/site-packages/urllib3/connectionpool.py", line 462, in _make_request
    httplib_response = conn.getresponse()
  File "/usr/local/lib/python3.10/http/client.py", line 1375, in getresponse
    response.begin()
  File "/usr/local/lib/python3.10/http/client.py", line 318, in begin
    version, status, reason = self._read_status()
  File "/usr/local/lib/python3.10/http/client.py", line 287, in _read_status
    raise RemoteDisconnected("Remote end closed connection without"
http.client.RemoteDisconnected: Remote end closed connection without response

During handling of the above exception, another exception occurred:

Traceback (most recent call last):
  File "/home/airflow/.local/lib/python3.10/site-packages/requests/adapters.py", line 486, in send
    resp = conn.urlopen(
  File "/home/airflow/.local/lib/python3.10/site-packages/urllib3/connectionpool.py", line 799, in urlopen
    retries = retries.increment(
  File "/home/airflow/.local/lib/python3.10/site-packages/urllib3/util/retry.py", line 550, in increment
    raise six.reraise(type(error), error, _stacktrace)
  File "/home/airflow/.local/lib/python3.10/site-packages/urllib3/packages/six.py", line 769, in reraise
    raise value.with_traceback(tb)
  File "/home/airflow/.local/lib/python3.10/site-packages/urllib3/connectionpool.py", line 715, in urlopen
    httplib_response = self._make_request(
  File "/home/airflow/.local/lib/python3.10/site-packages/urllib3/connectionpool.py", line 467, in _make_request
    six.raise_from(e, None)
  File "<string>", line 3, in raise_from
  File "/home/airflow/.local/lib/python3.10/site-packages/urllib3/connectionpool.py", line 462, in _make_request
    httplib_response = conn.getresponse()
  File "/usr/local/lib/python3.10/http/client.py", line 1375, in getresponse
    response.begin()
  File "/usr/local/lib/python3.10/http/client.py", line 318, in begin
    version, status, reason = self._read_status()
  File "/usr/local/lib/python3.10/http/client.py", line 287, in _read_status
    raise RemoteDisconnected("Remote end closed connection without"
urllib3.exceptions.ProtocolError: ('Connection aborted.', RemoteDisconnected('Remote end closed connection without response'))

During handling of the above exception, another exception occurred:

Traceback (most recent call last):
  File "/opt/airflow/dags/training_pipeline.py", line 59, in api_healthcheck
    r = requests.get(url, timeout=10)
  File "/home/airflow/.local/lib/python3.10/site-packages/requests/api.py", line 73, in get
    return request("get", url, params=params, **kwargs)
  File "/home/airflow/.local/lib/python3.10/site-packages/requests/api.py", line 59, in request
    return session.request(method=method, url=url, **kwargs)
  File "/home/airflow/.local/lib/python3.10/site-packages/requests/sessions.py", line 589, in request
    resp = self.send(prep, **send_kwargs)
  File "/home/airflow/.local/lib/python3.10/site-packages/requests/sessions.py", line 703, in send
    r = adapter.send(request, **kwargs)
  File "/home/airflow/.local/lib/python3.10/site-packages/requests/adapters.py", line 501, in send
    raise ConnectionError(err, request=request)
requests.exceptions.ConnectionError: ('Connection aborted.', RemoteDisconnected('Remote end closed connection without response'))

During handling of the above exception, another exception occurred:

Traceback (most recent call last):
  File "/home/airflow/.local/lib/python3.10/site-packages/airflow/operators/python.py", line 192, in execute
    return_value = self.execute_callable()
  File "/home/airflow/.local/lib/python3.10/site-packages/airflow/operators/python.py", line 209, in execute_callable
    return self.python_callable(*self.op_args, **self.op_kwargs)
  File "/opt/airflow/dags/training_pipeline.py", line 63, in api_healthcheck
    raise RuntimeError(f"API healthcheck falló para {url}: {e}")
RuntimeError: API healthcheck falló para http://10.43.101.149:80/docs: ('Connection aborted.', RemoteDisconnected('Remote end closed connection without response'))
[2025-10-06T02:00:25.482+0000] {taskinstance.py:1400} INFO - Marking task as UP_FOR_RETRY. dag_id=forest_cover_training_pipeline, task_id=api_healthcheck, execution_date=20251006T015000, start_date=20251006T020024, end_date=20251006T020025
[2025-10-06T02:00:25.497+0000] {standard_task_runner.py:104} ERROR - Failed to execute job 70 for task api_healthcheck (API healthcheck falló para http://10.43.101.149:80/docs: ('Connection aborted.', RemoteDisconnected('Remote end closed connection without response')); 4313)
[2025-10-06T02:00:25.536+0000] {local_task_job_runner.py:228} INFO - Task exited with return code 1
[2025-10-06T02:00:25.558+0000] {taskinstance.py:2778} INFO - 0 downstream tasks scheduled from follow-on schedule check
[2025-10-06T02:05:31.312+0000] {taskinstance.py:1159} INFO - Dependencies all met for dep_context=non-requeueable deps ti=<TaskInstance: forest_cover_training_pipeline.api_healthcheck scheduled__2025-10-06T01:50:00+00:00 [queued]>
[2025-10-06T02:05:31.499+0000] {taskinstance.py:1159} INFO - Dependencies all met for dep_context=requeueable deps ti=<TaskInstance: forest_cover_training_pipeline.api_healthcheck scheduled__2025-10-06T01:50:00+00:00 [queued]>
[2025-10-06T02:05:31.500+0000] {taskinstance.py:1361} INFO - Starting attempt 1 of 2
[2025-10-06T02:05:31.511+0000] {taskinstance.py:1382} INFO - Executing <Task(PythonOperator): api_healthcheck> on 2025-10-06 01:50:00+00:00
[2025-10-06T02:05:31.528+0000] {standard_task_runner.py:57} INFO - Started process 208 to run task
[2025-10-06T02:05:31.534+0000] {standard_task_runner.py:84} INFO - Running: ['***', 'tasks', 'run', 'forest_cover_training_pipeline', 'api_healthcheck', 'scheduled__2025-10-06T01:50:00+00:00', '--job-id', '3', '--raw', '--subdir', 'DAGS_FOLDER/training_pipeline.py', '--cfg-path', '/tmp/tmpczgxfys5']
[2025-10-06T02:05:31.540+0000] {standard_task_runner.py:85} INFO - Job 3: Subtask api_healthcheck
[2025-10-06T02:05:31.606+0000] {task_command.py:416} INFO - Running <TaskInstance: forest_cover_training_pipeline.api_healthcheck scheduled__2025-10-06T01:50:00+00:00 [running]> on host 2d6451742e7c
[2025-10-06T02:05:31.676+0000] {taskinstance.py:1662} INFO - Exporting env vars: AIRFLOW_CTX_DAG_OWNER='mlops_team' AIRFLOW_CTX_DAG_ID='forest_cover_training_pipeline' AIRFLOW_CTX_TASK_ID='api_healthcheck' AIRFLOW_CTX_EXECUTION_DATE='2025-10-06T01:50:00+00:00' AIRFLOW_CTX_TRY_NUMBER='1' AIRFLOW_CTX_DAG_RUN_ID='scheduled__2025-10-06T01:50:00+00:00'
[2025-10-06T02:05:31.721+0000] {logging_mixin.py:154} INFO - [healthcheck] GET http://10.43.100.103:8080/docs -> 200
[2025-10-06T02:05:31.722+0000] {python.py:194} INFO - Done. Returned value was: None
[2025-10-06T02:05:31.731+0000] {taskinstance.py:1400} INFO - Marking task as SUCCESS. dag_id=forest_cover_training_pipeline, task_id=api_healthcheck, execution_date=20251006T015000, start_date=20251006T020531, end_date=20251006T020531
[2025-10-06T02:05:31.758+0000] {local_task_job_runner.py:228} INFO - Task exited with return code 0
[2025-10-06T02:05:31.788+0000] {taskinstance.py:2778} INFO - 1 downstream tasks scheduled from follow-on schedule check
